### 一.Promise是什么

所谓`Promise`，简单说就是一个容器，里面保存着某个未来才会结束的事件（通常是一个异步操作）的结果。从语法上说，Promise 是一个对象，从它可以获取异步操作的消息。 

`Promise`对象有以下两个特点：

- 对象的状态不受外界影响。`Promise`对象代表一个异步操作，只有3中状态，`pending`、`ressolved`、`rejected`，状态只有异步操作的结果解决，任何其他的操作都无法改变状态。
- 一旦准状态改变，就不会再变，任何时候都可以得到这个结果。`Promise`对象的状态改变，只有两种可能：从`pending`变为`fulfilled`和从`pending`变为`rejected`。只要这两种情况发生，状态就凝固了，不会再变了，会一直保持这个结果 

`resolve`函数的作用是，将`Promise`对象的状态从“未完成”变为“成功”（即从 `pending` 变为` resolved`），在异步操作成功时调用，并将异步操作的结果，作为参数传递出去；

`reject`函数的作用是，将`Promise`对象的状态从“未完成”变为“失败”（即从 pending 变为 rejected），在异步操作失败时调用，并将异步操作报出的错误，作为参数传递出去。 

```javascript
let promise = new Promise(function(resolve, reject) {
  console.log('Promise');
  resolve(1);
});
console.log(promise);
//Promise
//Promise {<resolved>: 1}    
    __proto__: Promise
    [[PromiseStatus]]: "resolved"
    [[PromiseValue]]: 1
//Promise构造函数中的回调函数立即执行，输出Promise，promise是一个Promise对象，有两个属性，一个是状态，一个是值，值为resolve函数或者reject函数中的值。
```



### 二.Promise的使用

#### 1.基本使用

构造一个`Promise`对象，参数是一个回调函数，回调函数中两个参数，`resolve`和`rejecte`。

`Promise`构造函数中的回调函数会立即执行。

```javascript
let p1 = new Promise((resolve,reject)=>{
    if(...){
       resolve(...)//传到then第一个函数中的参数
    }
})
```

例1：

```javascript
	function timeout(ms){
		let p1 = new Promise(function(resolve,reject){
			setTimeout(function(){
				resolve('done')
			},ms,)
		})
		return p1;
	}
	timeout(3000).then(function(data){
		console.log(data);
		resolve(2);  //这里也会报错，如果想将data传到下一个then中，应该写 return 2；
	}).then((data) => {
		console.log(data)
	})
//ReferenceError: resolve is undefined
//因为setTimeout中的回调函数是在window下运行的


```

```javascript
	function timeout(ms){
		let p1 = new Promise(function(resolve,reject){
			setTimeout(resolve('done'),ms)
		})
		return p1;
	}
	timeout(3000).then(function(data){
		console.log(data);
		return 2;
	}).then((data) => {
		console.log(data)
	})
	//done
	//2
	
//解析：先定义了一个函数，当timeout(3000)时函数执行，返回了一个p1，p1又是一个Promise对象，Promise中的回调函数会立即执行，结果是一个异步操作---定时器，所以js继续向下执行，等到执行栈中没有任务，任务队列中的定时器的延迟时间到了过后，回调函数入栈，执行，resolve将Promise对象的状态有pending->resolved，所以会立即调用then中的第一个函数，打印data，这里的data是resolve函数传进来的参数。因为每一个then方法也是一个全新的Promise，return 会被Promise.resolve包装，然后又到了第二个then
```

例2：

```javascript
const getJson = function(url){
	const Promise = new Promise(fucntion(resolve,reject){
		let xhr = new XMLHttpRequest();
		xhr.open('POST',url,true);
		xhr.onreadystatechange = handle;
		xhr.setRequestHeader('Accept','application/json');
		function handle = function(){
			if(this.readyState !== 4){
				return
			}
			if(this.status === 200){
				resolve(this.response);
			}else{
				reject(new Error(this.statusText));
			}
		}
	})
	return Promise;
}
getJson('/posts.json').then(function(data){
	console.log(data);
},function(error){
	console.log(error)
})


```

`Promise` 实例具有then方法，也就是说，`then`方法是定义在原型对象`Promise.prototype`上的。它的作用是为` Promise` 实例添加状态改变时的回调函数。`then`方法的第一个参数是`resolved`状态的回调函数，第二个参数（可选）是`rejected`状态的回调函数。

`then`方法返回的是一个新的`Promise`实例（注意，不是原来那个Promise实例）。因此可以采用链式写法，即`then`方法后面再调用另一个`then`方法。

`then`方法是没有`resolve`方法的，改变状态是通过`return` ，`return`语句会通过`Promise.resolve`的包装，所以下一个`then`方法中一般只有一个回调函数。

如果想下一个`then`方法中还有两个方法，即一个成功的回调方法，另一个失败的回调函数。可以`return`一个`Promise`对象。也可用`catch`方法，捕捉前面所有的错误

`Primise`对象A中`resolve`的是另外一个`Promise`对象`B`，则`A`的状态完全`B`决定。

注意，调用`resolve`或`reject`并不会终结 Promise 的参数函数的执行。 函数继续往下执行，如果想要函数不继续执行，可以`return resolve（。。。）`



#### 2.catch语句

`Promise` 对象的错误具有“冒泡”性质，会一直向后传递，直到被捕获为止。也就是说，错误总是会被下一个`catch`语句捕获。如果没有使用`catch`方法指定错误处理的回调函数，`Promise` 对象抛出的错误不会传递到外层代码，即不会有任何反应。

```

getJSON('/posts.json').then(function(posts) {
  // ...
}).catch(function(error) {
  // 处理 getJSON 和 前一个回调函数运行时发生的错误
  console.log('发生错误！', error);
});



try 语句允许我们定义在执行时进行错误测试的代码块。
catch 语句允许我们定义当 try 代码块发生错误时，所执行的代码块。
finally 语句在 try 和 catch 之后无论有无异常都会执行
```

如果没有使用`catch`方法指定错误处理的回调函数，Promise 对象抛出的错误不会传递到外层代码，即不会有任何反应。会报错，但是代码会继续执行。

`catch`方法返回的还是一个` Promise` 对象，因此后面还可以接着调用`then`方法。 

```javascript
const someAsyncThing = function() {
  return new Promise(function(resolve, reject) {
    // 下面一行会报错，因为x没有声明
    resolve(x + 2);
  });
};

someAsyncThing()
.catch(function(error) {
  console.log('oh no', error);
})
.then(function() {
  console.log('carry on');
});
// oh no [ReferenceError: x is not defined]
// carry on
```

运行完`catch`方法指定的回调函数，会接着运行后面那个`then`方法指定的回调函数。如果没有报错，则会跳过`catch`方法。 

`catch`总结:

- `catch`用于捕获错误，它的范围是上一个catch到它之前的所有错误，但是不包括`Primise`中状态改变之后的再出现的错误。
- `Promise`中错误会往上冒泡，直到被捕获为止，所以，可能会跳过中间的所有`then`方法，直接到`catch`方法。同时如果`Promise`中的错误没有被捕获，不会影响外部的执行（会提示错误）
- 如果没有错误，`catch`会被跳过。
- `catch`语句会返回一个新的`Promise`对象，同时自动调用`Promise.resolve`，所以`catch`执行完后会直接执行下一个`then`方法

#### 3.Promise.all

`Promise.all`方法用于将多个 Promise 实例，包装成一个新的 Promise 实例。 

```javascript
Promise.all([p1,p2,p3])
```

上面代码中，`Promise.all`方法接受一个数组作为参数，`p1`、`p2`、`p3`都是 Promise 实例，如果不是，就会先调用`Promise.resolve`方法，将参数转为 Promise 实例，再进一步处理。（`Promise.all`方法的参数可以不是数组，但必须具有 Iterator 接口，且返回的每个成员都是 Promise 实例。）

`p`的状态由`p1`、`p2`、`p3`决定，分成两种情况。

（1）只有`p1`、`p2`、`p3`的状态都变成`fulfilled`，`p`的状态才会变成`fulfilled`，此时`p1`、`p2`、`p3`的返回值组成一个数组，传递给`p`的回调函数。

（2）只要`p1`、`p2`、`p3`之中有一个被`rejected`，`p`的状态就变成`rejected`，此时第一个被`reject`的实例的返回值，会传递给`p`的回调函数。

```javascript
const promise = [3,5,6,8].map((value)=>{
    return getJson('./post'+value+'.json')
})
Promise.all(promise).then((data)=>{
    ....
}).catch((error)=>{
    
})
```

```javascript
let p1 = new Promise(function(resolve){
	resolve(1);
})
undefined
let p2 = new Promise(function(resolve){
	resolve(2);
})
undefined
let p3 = new Promise(function(resolve){
	resolve(3);
})
let p = Promise.all([p1,p2,p3]);
console.log(p);
//Promise {<resolved>: Array(3)}
    __proto__: Promise
    [[PromiseStatus]]: "resolved"
    [[PromiseValue]]: Array(3)
 
```



注意，如果作为参数的 Promise 实例，自己定义了`catch`方法，那么它一旦被`rejected`，并不会触发`Promise.all()`的`catch`方法。 

```javascript
const p1 = new Promise((resolve, reject) => {
  resolve('hello');
})
.then(result => result)
.catch(e => e);

const p2 = new Promise((resolve, reject) => {
  throw new Error('报错了');
})
.then(result => result)
.catch(e => e);

Promise.all([p1, p2])
.then(result => console.log(result))
.catch(e => console.log(e));
// ["hello", Error: 报错了]

//上面代码中，p1会resolved，p2首先会rejected，但是p2有自己的catch方法，该方法返回的是一个新的 Promise 实例，p2指向的实际上是这个实例。该实例执行完catch方法后，也会变成resolved，导致Promise.all()方法参数里面的两个实例都会resolved，因此会调用then方法指定的回调函数，而不会调用catch方法指定的回调函数。
```

如果`p2`没有自己的`catch`方法，就会调用`Promise.all()`的`catch`方法。 

```javascript
const p1 = new Promise((resolve, reject) => {
  resolve('hello');
})
.then(result => result);

const p2 = new Promise((resolve, reject) => {
  throw new Error('报错了');
})
.then(result => result);

Promise.all([p1, p2])
.then(result => console.log(result))
.catch(e => console.log(e));
// Error: 报错了
```

#### 4.Promise.race

`Promise.race`方法同样是将多个Promise实例包装成一个Promise实例

```javascript
const p = Promise.all([p1,p2,p3])
```

只有p1、p2、p3中的一个实例率先改变状态，p的状态就发生改变，那个率先改变的 Promise 实例的返回值，就传递给`p`的回调函数。 